Workbook

Sheet 自学 （6级）
A2: 1 | B2: 过滤 | C2: Guòlǜ | D2: To filter, Filterate | F2: 这水得先过滤一下才能喝。 | G2: 你把那些没用的信息过滤掉吧。
A3: 2 | B3: 争夺 | C3: zhēngduó | D3: To fight for | F3: 两家公司在争夺同一个客户。 | G3: 他为了那个职位跟别人争夺了好几个月。
A4: 3 | B4: 将近 | C4: jiāngjìn | D4: Approximately | F4: 我在这里住了将近十年了。 | G4: 我们的目标完成率将近百分之九十。
A5: 4 | B5: 进而 | C5: jìn'ér | D5: And then | F5: 他先学了中文，进而开始研究中国文化。 | G5: 我希望先了解，再进而改进方法。
A6: 5 | B6: 况且 | C6: kuàngqiě | D6: Moreover, in addition | F6: 我今天太累了，况且明天还要早起。 | G6: 他不会去的，况且天气也不好。
A7: 6 | B7: 宁肯 | C7: nìngkěn | D7: Would rather | F7: 我宁肯多花点时间，也不想做错。 | G7: 他宁肯自己受累，也不愿麻烦别人。
A8: 7 | B8: 颇 | C8: pō | D8: Quite | F8: 他对这个问题颇有研究。 | G8: 这道菜味道颇不错。
A9: 8 | B9: 拣 | C9: jiǎn | D9: Pick up | F9: 我拣了几瓶矿泉水回来。 | G9: 你拣个颜色好看的吧。
A10: 9 | B10: 维持 | C10: wéichí | D10: To preserve, to maintain | F10: 我们得努力维持现在的生活水平。 | G10: 他们之间的关系很难维持下去。
A11: 10 | B11: 分裂 | C11: fēnliè | D11: To split, to divide | F11: 团队因为意见不合快要分裂了。 | G11: 家庭的分裂让孩子很难过。
A12: 11 | B12: 跟随 | C12: Gēnsuí | D12: Follow | F12: 我打算跟随师傅学一年。 | G12: 我打算跟随师傅学一年。
A13: 12 | B13: 寻觅 | C13: xúnmì | D13: To look for, seek for | F13: 我在城市里寻觅那家老餐馆。 | G13: 她一直在寻觅理想的工作。
... A148: 147 | B148: 决策 | C148: juécè | D148: to make a strategic decision | F148: 公司高层正在讨论新的发展决策。 | G148: 领导层经过反复讨论，最终作出了关键的战略决策。
A149: 148 | B149: 土壤 | C149: Tǔrǎng | D149: Soil | E149: 土壤不是很肥沃。
A150: 149 | B150: 陡峭 | C150: dǒuqiào | D150: Steep, Precipious | E150: 丝瓜已经爬上了我们大楼陡峭的楼墙。
A151: 150 | B151: 茂盛 | C151: màoshèng | D151: Luxuriant, exuberant | E151: 叶子茂盛
A152: 151 | B152: 悬挂 | C152: xuánguà | D152: to hang, to suspend | E152: 她悬挂在空中
A153: 152 | B153: 负担 | C153: fùdān | D153: to bear, to shoulder | E153: 丝瓜茎好像负担不起抓的重量。
A154: 153 | B154: 坠 | C154: zhuì | D154: to fall, to drop | E154: 时刻都要坠落下来
A155: 154 | B155: 吊 | C155: diào | D155: to hang, to suspend, to dangle | E155: 垂直地吊在那里
A156: 155 | B156: 点缀 | C156: diǎnzhuì | D156: to decorate, to adorn | E156: 黄色的花瓣点缀在绿叶之间。
A157: 156 | B157: 协调 | C157: xiétiáo | D157: coordinated, harmonious | E157: 颜色协调
A158: 157 | B158: 连同 | C158: liántóng | D158: together with, along with | E158: 连同上面的两个大丝瓜一起坠落到地下。
A159: 158 | B159: 断定 | C159: duàndìng | D159: to form judgement, to conclude | E159: 我断定的说
A160: 159 | B160: 晃 | C160: huǎng | D160: to shake, to sway | E160: 在风中晃来晃去
... A179: 178 | B179: 跳跃 | C179: tiàoyuè | D179: to jump, to leap | E179: 猫为什么能快速跳跃起来
A180: 179 | B180: 间隔 | C180: jiàngé | D180: interval, intermission
A181: 180 | B181: 姑且 | C181: gūqiě | D181: fo the moment, tentatively | E181: 他们姑且换一个文雅的称呼吧
A182: 181 | B182: 笨拙 | C182: bènzhuō | D182: clumsy, stupid | E182: 笨拙的大象
A183: 182 | B183: 闪烁 | C183: shǎnshuò | D183: to twinkle, to flicker, to glitter | E183: 他们看到的是一明一暗的闪烁
A184: 183 | B184: 实力 | C184: shílì | D184: vision, eyesight | E184: 我们的实力看到的就会是一个连续的光
A185: 184 | B185: 文雅 | C185: wényǎ | D185: elegant, refined, polished | E185: 他们姑且换一个文雅的称呼吧
A186: 185 | B186: 新陈代谢 （代谢） | C186: xīnchéndàixiè (dàixiè) | D186: metabolism | E186: 新陈代谢速率有效
A187: 186 | B187: 名次 | C187: míngcì | D187: ranking, place in a competition
A188: 187 | B188: 推论 | C188: tuīlùn | D188: to infer, to deduce
A189: 188 | B189: 实惠 | C189: shíhuì | D189: practical, affordable, substantial
A190: 189 | B190: 渺小 | C190: miǎoxiǎo | D190: tiny, insgnificant
A191: 190 | B191: 焦急 | C191: jiāojí | D191: anxious, agitated
A192: 191 | B192: 系列 | C192: xìliè | D192: series, set
A193: 192 | B193: 深奥 | C193: shēn'ào | D193: deep, abstruse
...

Sheet Sheet1
A1: Column1 | B1: Column2 | C1: Column3 | D1: Column4 | F1: 巴不得 – eagerly wish, can't wait for
A2: 一向 | D2: 巴不得 | F2: 我巴不得明天就能见到你。 / I can’t wait to see you tomorrow.
A3: 一度 | D3: 别提多。。。了
A4: 不妨 | D4: 恨不得 | F4: 别提多。。。了 – extremely, you can’t imagine how…
A5: 不得已 | D5: 顿时 | F5: 这道菜好吃得别提多了！ / This dish is incredibly delicious!
A6: 不料 | D6: 不由得
A7: 不禁 | D7: 番 | F7: 恨不得 – wish one could, eager to
A8: 不顾 | D8: 过于 | F8: 我恨不得立刻搬到海边去住。 / I wish I could move to the seaside immediately.
A9: 仍旧 | D9: 着呢
A10: 令人 | D10: 乘机 | F10: 顿时 – instantly, at once
A11: 以便 | D11: 不料 | F11: 听到这个消息，他顿时愣住了。 / Hearing the news, he was instantly stunned.
A12: 以致 | D12: 未免
A13: 例外 | D13: 而已 | F13: 不由得 – can’t help but
A14: 依旧 | D14: 固然 | F14: 看到孩子们玩耍，我不由得笑了。 / Seeing the children playing, I couldn’t help but laugh.
A15: 便于 | D15: 无非
A16: 便于 | D16: 唯独 | F16: 番 – (measure word for efforts or times)
A17: 倘若 | D17: 明明 | F17: 他又试了一番，终于成功了。 / He tried again and finally succeeded.
A18: 免得 | D18: 大不了
A19: 况且 | D19: 于 | F19: 过于 – excessively
A20: 创立 | D20: 致使 | F20: 你过于担心没必要。 / You are worrying excessively, which is unnecessary.
A21: 刹那 | D21: 并非
A22: 务必 | D22: 对。。。而言 | F22: 着呢 – emphasizing a state (colloquial)
A23: 勉强 | D23: 有关 | F23: 他忙着呢，别打扰他。 / He’s busy, don’t disturb him.
A24: 即时 | D24: 不瞒你说
A25: 历来 | D25: 以至 | F25: 乘机 – take advantage of an opportunity
A26: 及早 | D26: 即便 | F26: 他乘机解释了自己的观点。 / He took the opportunity to explain his point of view.
A27: 固然 | D27: 所在
A28: 大不了 | D28: 统统 | F28: 不料 – unexpectedly
A29: 姑且 | D29: 该干吗干吗 | F29: 不料今天竟然下起了大雨。 / Unexpectedly, it rained heavily today.
A30: 宁肯 | D30: 不妨
A31: 将就 | D31: 务必 | F31: 未免 – rather, a bit too
A32: 将近 | D32: 鉴于 | F32: 他说话未免太直接了。 / He speaks rather too directly.
A33: 巴不得 | D33: 便于
A34: 并非 | D34: 犹如 | F34: 而已 – only, that’s all
A35: 当初 | D35: 和。。。相比 | F35: 我只是随便看看而已。 / I’m just casually looking, that’s all.
A36: 忍受 | D36: 难以
A37: 恰巧 | D37: 免得 | F37: 固然 – admittedly, it is true
A38: 无非 | D38: 时而 | F38: 固然他很忙，但还是抽时间来看我。 / Admittedly, he is busy, but he still took time to visit me.
A39: 时而 | D39: 不禁
A40: 未免 | D40: 无不 | F40: 无非 – nothing but
...

Sheet Test
C1: Result | D1: Answer | F1: =H15 -> 158 | K1: =H16 -> 36
A2: ='自学 （6级）'!D2 -> To filter, Filterate | C2: =IF(OR(ISBLANK(B2),'自学 （6级）'!B2=""),"UNANSWERED", IF('自学 （6级）'!B2=B2,"TRUE","FALSE")) -> UNANSWERED | D2: =IF(OR(ISBLANK(B2),ISBLANK('自学 （6级）'!B2)),"", IF(B2='自学 （6级）'!B2,"",'自学 （6级）'!B2))
A3: ='自学 （6级）'!D3 -> To fight for | C3: =IF(OR(ISBLANK(B3),'自学 （6级）'!B3=""),"UNANSWERED", IF('自学 （6级）'!B3=B3,"TRUE","FALSE")) -> UNANSWERED | D3: =IF(OR(ISBLANK(B3),ISBLANK('自学 （6级）'!B3)),"", IF(B3='自学 （6级）'!B3,"",'自学 （6级）'!B3))
A4: ='自学 （6级）'!D4 -> Approximately | C4: =IF(OR(ISBLANK(B4),'自学 （6级）'!B4=""),"UNANSWERED", IF('自学 （6级）'!B4=B4,"TRUE","FALSE")) -> UNANSWERED | D4: =IF(OR(ISBLANK(B4),ISBLANK('自学 （6级）'!B4)),"", IF(B4='自学 （6级）'!B4,"",'自学 （6级）'!B4))
A5: ='自学 （6级）'!D5 -> And then | C5: =IF(OR(ISBLANK(B5),'自学 （6级）'!B5=""),"UNANSWERED", IF('自学 （6级）'!B5=B5,"TRUE","FALSE")) -> UNANSWERED | D5: =IF(OR(ISBLANK(B5),ISBLANK('自学 （6级）'!B5)),"", IF(B5='自学 （6级）'!B5,"",'自学 （6级）'!B5))
A6: ='自学 （6级）'!D6 -> Moreover, in addition | C6: =IF(OR(ISBLANK(B6),'自学 （6级）'!B6=""),"UNANSWERED", IF('自学 （6级）'!B6=B6,"TRUE","FALSE")) -> UNANSWERED | D6: =IF(OR(ISBLANK(B6),ISBLANK('自学 （6级）'!B6)),"", IF(B6='自学 （6级）'!B6,"",'自学 （6级）'!B6))
A7: ='自学 （6级）'!D7 -> Would rather | C7: =IF(OR(ISBLANK(B7),'自学 （6级）'!B7=""),"UNANSWERED", IF('自学 （6级）'!B7=B7,"TRUE","FALSE")) -> UNANSWERED | D7: =IF(OR(ISBLANK(B7),ISBLANK('自学 （6级）'!B7)),"", IF(B7='自学 （6级）'!B7,"",'自学 （6级）'!B7))
A8: ='自学 （6级）'!D8 -> Quite | C8: =IF(OR(ISBLANK(B8),'自学 （6级）'!B8=""),"UNANSWERED", IF('自学 （6级）'!B8=B8,"TRUE","FALSE")) -> UNANSWERED | D8: =IF(OR(ISBLANK(B8),ISBLANK('自学 （6级）'!B8)),"", IF(B8='自学 （6级）'!B8,"",'自学 （6级）'!B8))
A9: ='自学 （6级）'!D9 -> Pick up | C9: =IF(OR(ISBLANK(B9),'自学 （6级）'!B9=""),"UNANSWERED", IF('自学 （6级）'!B9=B9,"TRUE","FALSE")) -> UNANSWERED | D9: =IF(OR(ISBLANK(B9),ISBLANK('自学 （6级）'!B9)),"", IF(B9='自学 （6级）'!B9,"",'自学 （6级）'!B9))
A10: ='自学 （6级）'!D10 -> To preserve, to maintain | C10: =IF(OR(ISBLANK(B10),'自学 （6级）'!B10=""),"UNANSWERED", IF('自学 （6级）'!B10=B10,"TRUE","FALSE")) -> UNANSWERED | D10: =IF(OR(ISBLANK(B10),ISBLANK('自学 （6级）'!B10)),"", IF(B10='自学 （6级）'!B10,"",'自学 （6级）'!B10)) | F10: =(F1/312) -> 0.50641026
A11: ='自学 （6级）'!D11 -> To split, to divide | C11: =IF(OR(ISBLANK(B11),'自学 （6级）'!B11=""),"UNANSWERED", IF('自学 （6级）'!B11=B11,"TRUE","FALSE")) -> UNANSWERED | D11: =IF(OR(ISBLANK(B11),ISBLANK('自学 （6级）'!B11)),"", IF(B11='自学 （6级）'!B11,"",'自学 （6级）'!B11))
A12: ='自学 （6级）'!D12 -> Follow | C12: =IF(OR(ISBLANK(B12),'自学 （6级）'!B12=""),"UNANSWERED", IF('自学 （6级）'!B12=B12,"TRUE","FALSE")) -> UNANSWERED | D12: =IF(OR(ISBLANK(B12),ISBLANK('自学 （6级）'!B12)),"", IF(B12='自学 （6级）'!B12,"",'自学 （6级）'!B12))
A13: ='自学 （6级）'!D13 -> To look for, seek for | C13: =IF(OR(ISBLANK(B13),'自学 （6级）'!B13=""),"UNANSWERED", IF('自学 （6级）'!B13=B13,"TRUE","FALSE")) -> UNANSWERED | D13: =IF(OR(ISBLANK(B13),ISBLANK('自学 （6级）'!B13)),"", IF(B13='自学 （6级）'!B13,"",'自学 （6级）'!B13))
A14: ='自学 （6级）'!D14 -> Exaggeration | C14: =IF(OR(ISBLANK(B14),'自学 （6级）'!B14=""),"UNANSWERED", IF('自学 （6级）'!B14=B14,"TRUE","FALSE")) -> UNANSWERED | D14: =IF(OR(ISBLANK(B14),ISBLANK('自学 （6级）'!B14)),"", IF(B14='自学 （6级）'!B14,"",'自学 （6级）'!B14))
A15: ='自学 （6级）'!D15 -> Clearly, plainly | C15: =IF(OR(ISBLANK(B15),'自学 （6级）'!B15=""),"UNANSWERED", IF('自学 （6级）'!B15=B15,"TRUE","FALSE")) -> UNANSWERED | D15: =IF(OR(ISBLANK(B15),ISBLANK('自学 （6级）'!B15)),"", IF(B15='自学 （6级）'!B15,"",'自学 （6级）'!B15)) | G15: Mark | H15: =SUMPRODUCT(--(TRIM(C2:C312)="TRUE")) -> 158 | L15: =F1/COUNTIFS(C2:C312,"UNANSWERED") -> 1.3504274
A16: ='自学 （6级）'!D16 -> Greedy | C16: =IF(OR(ISBLANK(B16),'自学 （6级）'!B16=""),"UNANSWERED", IF('自学 （6级）'!B16=B16,"TRUE","FALSE")) -> UNANSWERED | D16: =IF(OR(ISBLANK(B16),ISBLANK('自学 （6级）'!B16)),"", IF(B16='自学 （6级）'!B16,"",'自学 （6级）'!B16)) | G16: Lose | H16: =SUMPRODUCT(--(TRIM($C$2:$C$312)="FALSE")) -> 36
A17: ='自学 （6级）'!D17 -> All through ages, always | C17: =IF(OR(ISBLANK(B17),'自学 （6级）'!B17=""),"UNANSWERED", IF('自学 （6级）'!B17=B17,"TRUE","FALSE")) -> UNANSWERED | D17: =IF(OR(ISBLANK(B17),ISBLANK('自学 （6级）'!B17)),"", IF(B17='自学 （6级）'!B17,"",'自学 （6级）'!B17)) | G17: Total
A18: ='自学 （6级）'!D18 -> To lose, forfeit | C18: =IF(OR(ISBLANK(B18),'自学 （6级）'!B18=""),"UNANSWERED", IF('自学 （6级）'!B18=B18,"TRUE","FALSE")) -> UNANSWERED | D18: =IF(OR(ISBLANK(B18),ISBLANK('自学 （6级）'!B18)),"", IF(B18='自学 （6级）'!B18,"",'自学 （6级）'!B18))
A19: ='自学 （6级）'!D19 -> Endure | C19: =IF(OR(ISBLANK(B19),'自学 （6级）'!B19=""),"UNANSWERED", IF('自学 （6级）'!B19=B19,"TRUE","FALSE")) -> UNANSWERED | D19: =IF(OR(ISBLANK(B19),ISBLANK('自学 （6级）'!B19)),"", IF(B19='自学 （6级）'!B19,"",'自学 （6级）'!B19)) | G19: Day 1 | H19: Day 2 | I19: Day 3 | J19: Day 4 | K19: Day 5 | L19: Day 6 | M19: Day 7
A20: ='自学 （6级）'!D20 -> Taste, Flavor | C20: =IF(OR(ISBLANK(B20),'自学 （6级）'!B20=""),"UNANSWERED", IF('自学 （6级）'!B20=B20,"TRUE","FALSE")) -> UNANSWERED | D20: =IF(OR(ISBLANK(B20),ISBLANK('自学 （6级）'!B20)),"", IF(B20='自学 （6级）'!B20,"",'自学 （6级）'!B20)) | G20: 诱惑
A21: ='自学 （6级）'!D21 -> To firmly believe | C21: =IF(OR(ISBLANK(B21),'自学 （6级）'!B21=""),"UNANSWERED", IF('自学 （6级）'!B21=B21,"TRUE","FALSE")) -> UNANSWERED | D21: =IF(OR(ISBLANK(B21),ISBLANK('自学 （6级）'!B21)),"", IF(B21='自学 （6级）'!B21,"",'自学 （6级）'!B21)) | G21: 熬
A22: ='自学 （6级）'!D22 -> Forthright | C22: =IF(OR(ISBLANK(B22),'自学 （6级）'!B22=""),"UNANSWERED", IF('自学 （6级）'!B22=B22,"TRUE","FALSE")) -> UNANSWERED | D22: =IF(OR(ISBLANK(B22),ISBLANK('自学 （6级）'!B22)),"", IF(B22='自学 （6级）'!B22,"",'自学 （6级）'!B22)) | G22: 酝酿
A23: ='自学 （6级）'!D23 -> On good term with | C23: =IF(OR(ISBLANK(B23),'自学 （6级）'!B23=""),"UNANSWERED", IF('自学 （6级）'!B23=B23,"TRUE","FALSE")) -> UNANSWERED | D23: =IF(OR(ISBLANK(B23),ISBLANK('自学 （6级）'!B23)),"", IF(B23='自学 （6级）'!B23,"",'自学 （6级）'!B23)) | G23: 流露
A24: ='自学 （6级）'!D24 -> Harmonious | C24: =IF(OR(ISBLANK(B24),'自学 （6级）'!B24=""),"UNANSWERED", IF('自学 （6级）'!B24=B24,"TRUE","FALSE")) -> UNANSWERED | D24: =IF(OR(ISBLANK(B24),ISBLANK('自学 （6级）'!B24)),"", IF(B24='自学 （6级）'!B24,"",'自学 （6级）'!B24)) | G24: 操劳
A25: ='自学 （6级）'!D25 -> To chime with | C25: =IF(OR(ISBLANK(B25),'自学 （6级）'!B25=""),"UNANSWERED", IF('自学 （6级）'!B25=B25,"TRUE","FALSE")) -> UNANSWERED | D25: =IF(OR(ISBLANK(B25),ISBLANK('自学 （6级）'!B25)),"", IF(B25='自学 （6级）'!B25,"",'自学 （6级）'!B25)) | G25: 惦记
A26: ='自学 （6级）'!D26 -> ignore | C26: =IF(OR(ISBLANK(B26),'自学 （6级）'!B26=""),"UNANSWERED", IF('自学 （6级）'!B26=B26,"TRUE","FALSE")) -> UNANSWERED | D26: =IF(OR(ISBLANK(B26),ISBLANK('自学 （6级）'!B26)),"", IF(B26='自学 （6级）'!B26,"",'自学 （6级）'!B26)) | G26: 设置
A27: ='自学 （6级）'!D27 -> instant | C27: =IF(OR(ISBLANK(B27),'自学 （6级）'!B27=""),"UNANSWERED", IF('自学 （6级）'!B27=B27,"TRUE","FALSE")) -> UNANSWERED | D27: =IF(OR(ISBLANK(B27),ISBLANK('自学 （6级）'!B27)),"", IF(B27='自学 （6级）'!B27,"",'自学 （6级）'!B27)) | G27: 机构
A28: ='自学 （6级）'!D28 -> industrious, diligent | C28: =IF(OR(ISBLANK(B28),'自学 （6级）'!B28=""),"UNANSWERED", IF('自学 （6级）'!B28=B28,"TRUE","FALSE")) -> UNANSWERED | D28: =IF(OR(ISBLANK(B28),ISBLANK('自学 （6级）'!B28)),"", IF(B28='自学 （6级）'!B28,"",'自学 （6级）'!B28)) | G28: 反感
A29: ='自学 （6级）'!D29 -> delicious food | C29: =IF(OR(ISBLANK(B29),'自学 （6级）'!B29=""),"UNANSWERED", IF('自学 （6级）'!B29=B29,"TRUE","FALSE")) -> UNANSWERED | D29: =IF(OR(ISBLANK(B29),ISBLANK('自学 （6级）'!B29)),"", IF(B29='自学 （6级）'!B29,"",'自学 （6级）'!B29)) | G29: 不料
A30: ='自学 （6级）'!D30 -> to be eager | C30: =IF(OR(ISBLANK(B30),'自学 （6级）'!B30=""),"UNANSWERED", IF('自学 （6级）'!B30=B30,"TRUE","FALSE")) -> UNANSWERED | D30: =IF(OR(ISBLANK(B30),ISBLANK('自学 （6级）'!B30)),"", IF(B30='自学 （6级）'!B30,"",'自学 （6级）'!B30)) | G30: 未免
A31: ='自学 （6级）'!D31 -> to shout | C31: =IF(OR(ISBLANK(B31),'自学 （6级）'!B31=""),"UNANSWERED", IF('自学 （6级）'!B31=B31,"TRUE","FALSE")) -> UNANSWERED | D31: =IF(OR(ISBLANK(B31),ISBLANK('自学 （6级）'!B31)),"", IF(B31='自学 （6级）'!B31,"",'自学 （6级）'!B31)) | G31: 悲惨
... A45: ='自学 （6级）'!D45 -> to conceal | C45: =IF(OR(ISBLANK(B45),'自学 （6级）'!B45=""),"UNANSWERED", IF('自学 （6级）'!B45=B45,"TRUE","FALSE")) -> UNANSWERED | D45: =IF(OR(ISBLANK(B45),ISBLANK('自学 （6级）'!B45)),"", IF(B45='自学 （6级）'!B45,"",'自学 （6级）'!B45)) | G45: 意志
A46: ='自学 （6级）'!D46 -> to blame, to complain | C46: =IF(OR(ISBLANK(B46),'自学 （6级）'!B46=""),"UNANSWERED", IF('自学 （6级）'!B46=B46,"TRUE","FALSE")) -> UNANSWERED | D46: =IF(OR(ISBLANK(B46),ISBLANK('自学 （6级）'!B46)),"", IF(B46='自学 （6级）'!B46,"",'自学 （6级）'!B46))
A47: ='自学 （6级）'!D47 -> unusual, abnormal | C47: =IF(OR(ISBLANK(B47),'自学 （6级）'!B47=""),"UNANSWERED", IF('自学 （6级）'!B47=B47,"TRUE","FALSE")) -> UNANSWERED | D47: =IF(OR(ISBLANK(B47),ISBLANK('自学 （6级）'!B47)),"", IF(B47='自学 （6级）'!B47,"",'自学 （6级）'!B47))
A48: ='自学 （6级）'!D48 -> to endure | C48: =IF(OR(ISBLANK(B48),'自学 （6级）'!B48=""),"UNANSWERED", IF('自学 （6级）'!B48=B48,"TRUE","FALSE")) -> UNANSWERED | D48: =IF(OR(ISBLANK(B48),ISBLANK('自学 （6级）'!B48)),"", IF(B48='自学 （6级）'!B48,"",'自学 （6级）'!B48))
A49: ='自学 （6级）'!D49 -> to ferment | C49: =IF(OR(ISBLANK(B49),'自学 （6级）'!B49=""),"UNANSWERED", IF('自学 （6级）'!B49=B49,"TRUE","FALSE")) -> UNANSWERED | D49: =IF(OR(ISBLANK(B49),ISBLANK('自学 （6级）'!B49)),"", IF(B49='自学 （6级）'!B49,"",'自学 （6级）'!B49))
A50: ='自学 （6级）'!D50 -> Face to face | C50: =IF(OR(ISBLANK(B50),'自学 （6级）'!B50=""),"UNANSWERED", IF('自学 （6级）'!B50=B50,"TRUE","FALSE")) -> UNANSWERED | D50: =IF(OR(ISBLANK(B50),ISBLANK('自学 （6级）'!B50)),"", IF(B50='自学 （6级）'!B50,"",'自学 （6级）'!B50))
A51: ='自学 （6级）'!D51 -> Hesitate | C51: =IF(OR(ISBLANK(B51),'自学 （6级）'!B51=""),"UNANSWERED", IF('自学 （6级）'!B51=B51,"TRUE","FALSE")) -> UNANSWERED | D51: =IF(OR(ISBLANK(B51),ISBLANK('自学 （6级）'!B51)),"", IF(B51='自学 （6级）'!B51,"",'自学 （6级）'!B51))
A52: ='自学 （6级）'!D52 -> To look up and down | C52: =IF(OR(ISBLANK(B52),'自学 （6级）'!B52=""),"UNANSWERED", IF('自学 （6级）'!B52=B52,"TRUE","FALSE")) -> UNANSWERED | D52: =IF(OR(ISBLANK(B52),ISBLANK('自学 （6级）'!B52)),"", IF(B52='自学 （6级）'!B52,"",'自学 （6级）'!B52))
A53: ='自学 （6级）'!D53 -> To rub ones hand | C53: =IF(OR(ISBLANK(B53),'自学 （6级）'!B53=""),"UNANSWERED", IF('自学 （6级）'!B53=B53,"TRUE","FALSE")) -> UNANSWERED | D53: =IF(OR(ISBLANK(B53),ISBLANK('自学 （6级）'!B53)),"", IF(B53='自学 （6级）'!B53,"",'自学 （6级）'!B53))
...
